<?xml version="1.0" ?>
<sdf version="1.5">
  <world name="default">
    <scene>
      <sky>
        <clouds>
          <speed>12</speed>
        </clouds>
      </sky>
      <ambient>0.95 0.95 0.95 1</ambient>
      <background>0.3 0.3 0.3 1</background>
      <shadows>true</shadows>
    </scene>
    <!-- A global light source -->
    <include>
      <uri>model://sun</uri>
    </include>

    <include>
      <uri>model://baylands</uri>
    </include>

    <spherical_coordinates>
      <surface_model>EARTH_WGS84</surface_model>
      <latitude_deg>37.413534</latitude_deg>
      <longitude_deg>-121.996561</longitude_deg>
      <elevation>1.3</elevation>
    </spherical_coordinates>

    <physics name='default_physics' default='0' type='ode'>
      <gravity>0 0 -9.8066</gravity>
      <ode>
        <solver>
          <type>quick</type>
          <iters>10</iters>
          <sor>1.3</sor>
          <use_dynamic_moi_rescaling>0</use_dynamic_moi_rescaling>
        </solver>
        <constraints>
          <cfm>0</cfm>
          <erp>0.2</erp>
          <contact_max_correcting_vel>100</contact_max_correcting_vel>
          <contact_surface_layer>0.001</contact_surface_layer>
        </constraints>
      </ode>
      <max_step_size>0.004</max_step_size>
      <real_time_factor>1</real_time_factor>
      <real_time_update_rate>250</real_time_update_rate>
      <magnetic_field>6.0e-6 2.3e-5 -4.2e-5</magnetic_field>
    </physics>

    <model name='jetson' canonical_link='base_link'>
      <link name='cameraChassis'>
        <pose relative_to='base_link'>0.07 0 0.0385 0 -0 0</pose>
        <inertial>
          <mass>0.038</mass>
          <inertia>
            <ixx>1e-06</ixx>
            <ixy>0</ixy>
            <ixz>0</ixz>
            <iyy>1e-06</iyy>
            <iyz>0</iyz>
            <izz>1e-06</izz>
          </inertia>
          <pose>0 0 0 0 -0 0</pose>
        </inertial>
        <visual name='visual'>
          <geometry>
            <box>
              <size>0.01 0.085 0.01</size>
            </box>
          </geometry>
          <material>
            <ambient>0 0 1 1</ambient>
            <diffuse>0 0 1 1</diffuse>
            <specular>0 0 1 1</specular>
          </material>
        </visual>
        <collision name='collision'>
          <geometry>
            <box>
              <size>0.01 0.085 0.01</size>
            </box>
          </geometry>
          <max_contacts>10</max_contacts>
          <surface>
            <contact>
              <ode/>
            </contact>
            <bounce/>
            <friction>
              <torsional>
                <ode/>
              </torsional>
              <ode/>
            </friction>
          </surface>
        </collision>
        <self_collide>0</self_collide>
        <enable_wind>0</enable_wind>
        <kinematic>0</kinematic>
      </link>
      <link name='base_link'>
        <pose relative_to='__model__'>0 0 0.5 0 -0 0</pose>
        <inertial>
          <mass>0.8</mass>
          <inertia>
            <ixx>0.004</ixx>
            <ixy>0</ixy>
            <ixz>0</ixz>
            <iyy>0.004</iyy>
            <iyz>0</iyz>
            <izz>0.004</izz>
          </inertia>
          <pose>0 0 0 0 -0 0</pose>
        </inertial>
        <visual name='visual'>
          <geometry>
            <box>
              <size>0.133 0.085 0.053</size>
            </box>
          </geometry>
          <material>
            <ambient>0 0 1 1</ambient>
            <diffuse>0 0 1 1</diffuse>
            <specular>0 0 1 1</specular>
          </material>
        </visual>
        <collision name='collision'>
          <geometry>
            <box>
              <size>0.133 0.085 0.053</size>
            </box>
          </geometry>
          <max_contacts>10</max_contacts>
          <surface>
            <contact>
              <ode/>
            </contact>
            <bounce/>
            <friction>
              <torsional>
                <ode/>
              </torsional>
              <ode/>
            </friction>
          </surface>
        </collision>
        <sensor name='camera/left' type='camera'>
          <pose relative_to='camera_chassis'>0.0665 0.03649 0.0395 0 -0 0</pose>
          <topic>camera/left/</topic>
          <camera>
            <horizontal_fov>2.70526</horizontal_fov>
            <image>
              <width>500</width>
              <height>300</height>
              <format>L8</format>
            </image>
            <clip>
              <near>0.1</near>
              <far>100</far>
            </clip>
            <lens>
              <intrinsics>
                <fx>307.99879313442784</fx>
                <fy>328.57751082369407</fy>
                <cx>280.24657373225784</cx>
                <cy>134.9335316514946</cy>
                <s>0</s>
              </intrinsics>
              <!-- <type>stereographic</type>
              <scale_to_hfov>1</scale_to_hfov> -->
              <projection>
                <p_fx>312.8884288345382</p_fx>
                <p_fy>312.8884288345382</p_fy>
                <p_cx>312.28302001953125</p_cx>
                <p_cy>135.72957611083984</p_cy>
                <tx>0.0</tx>
                <ty>0.0</ty>
              </projection>
            </lens>
          </camera>
          <always_on>1</always_on>
          <update_rate>4</update_rate>
          <visualize>1</visualize>
          <plugin name='camera_left_controller' filename='libgazebo_ros_camera.so'>
            <frame_name>camera_left</frame_name>
          </plugin>
        </sensor>
        <sensor name='camera/right' type='camera'>
          <pose relative_to='camera_chassis'>0.0665 -0.03649 0.0395 0 -0 0</pose>
          <topic>camera/right/</topic>
          <camera>
            <horizontal_fov>2.70526</horizontal_fov>
            <image>
              <width>500</width>
              <height>300</height>
              <format>L8</format>
            </image>
            <clip>
              <near>0.1</near>
              <far>100</far>
            </clip>
            <lens>
              <intrinsics>
                <fx>307.1754049460059</fx>
                <fy>328.803046449949</fy>
                <cx>265.74658118131305</cx>
                <cy>141.73334383034592</cy>
                <s>0</s>
              </intrinsics>
              <!-- <type>stereographic</type>
              <scale_to_hfov>1</scale_to_hfov> -->
              <projection>
                <p_fx>312.8884288345382</p_fx>
                <p_fy>312.8884288345382</p_fy>
                <p_cx>312.28302001953125</p_cx>
                <p_cy>135.72957611083984</p_cy>
                <tx>-22.834775948524072</tx>
                <ty>0.0</ty>
              </projection>
            </lens>
          </camera>
          <always_on>1</always_on>
          <update_rate>4</update_rate>
          <visualize>1</visualize>
          <plugin name='camera_right_controller' filename='libgazebo_ros_camera.so'>
            <frame_name>camera_right</frame_name>
          </plugin>
        </sensor>
        <self_collide>0</self_collide>
        <enable_wind>0</enable_wind>
        <kinematic>0</kinematic>
        <plugin name='camera_right_controller' filename='libgazebo_ros_camera.so'>
          <frame_name>cameraRight</frame_name>
        </plugin>
      </link>
      <link name='leftWheel'>
        <pose relative_to='base_link'>0.035 0.044 -0.012 -1.5707 0 0</pose>
        <inertial>
          <mass>0.017</mass>
          <inertia>
            <ixx>1e-06</ixx>
            <ixy>0</ixy>
            <ixz>0</ixz>
            <iyy>1e-06</iyy>
            <iyz>0</iyz>
            <izz>1e-06</izz>
          </inertia>
          <pose>0 0 0 0 -0 0</pose>
        </inertial>
        <visual name='visual'>
          <geometry>
            <cylinder>
              <radius>0.0285</radius>
              <length>0.004</length>
            </cylinder>
          </geometry>
          <material>
            <ambient>1 0 0 1</ambient>
            <diffuse>1 0 0 1</diffuse>
            <specular>1 0 0 1</specular>
          </material>
        </visual>
        <collision name='collision'>
          <geometry>
            <cylinder>
              <radius>0.0285</radius>
              <length>0.004</length>
            </cylinder>
            <surface>
              <friction>
                <ode>
                  <mu>0.8</mu>
                  <mu2>0.8</mu2>
                </ode>
              </friction>
            </surface>
          </geometry>
          <max_contacts>10</max_contacts>
          <surface>
            <contact>
              <ode/>
            </contact>
            <bounce/>
            <friction>
              <torsional>
                <ode/>
              </torsional>
              <ode/>
            </friction>
          </surface>
        </collision>
        <self_collide>0</self_collide>
        <enable_wind>0</enable_wind>
        <kinematic>0</kinematic>
      </link>
      <link name='rightWheel'>
        <pose relative_to='base_link'>0.035 -0.044 -0.012 -1.5707 0 0</pose>
        <inertial>
          <mass>0.017</mass>
          <inertia>
            <ixx>2e-05</ixx>
            <ixy>0</ixy>
            <ixz>0</ixz>
            <iyy>2e-05</iyy>
            <iyz>0</iyz>
            <izz>4.1e-05</izz>
          </inertia>
          <pose>0 0 0 0 -0 0</pose>
        </inertial>
        <visual name='visual'>
          <geometry>
            <cylinder>
              <radius>0.0285</radius>
              <length>0.004</length>
            </cylinder>
            <surface>
              <friction>
                <ode>
                  <mu>0.8</mu>
                  <mu2>0.8</mu2>
                </ode>
              </friction>
            </surface>
          </geometry>
          <material>
            <ambient>1 0 0 1</ambient>
            <diffuse>1 0 0 1</diffuse>
            <specular>1 0 0 1</specular>
          </material>
        </visual>
        <collision name='collision'>
          <geometry>
            <cylinder>
              <radius>0.0285</radius>
              <length>0.004</length>
            </cylinder>
            <surface>
              <friction>
                <ode>
                  <mu>0.8</mu>
                  <mu2>0.8</mu2>
                </ode>
              </friction>
            </surface>
          </geometry>
          <max_contacts>10</max_contacts>
          <surface>
            <contact>
              <ode/>
            </contact>
            <bounce/>
            <friction>
              <torsional>
                <ode/>
              </torsional>
              <ode/>
            </friction>
          </surface>
        </collision>
        <self_collide>0</self_collide>
        <enable_wind>0</enable_wind>
        <kinematic>0</kinematic>
      </link>
      <frame name='caster_frame' attached_to='base_link'>
        <pose>-0.05 0 -0.0271 0 -0 0</pose>
      </frame>
      <link name='caster'>
        <pose relative_to='caster_frame'>0 0 0 0 -0 0</pose>
        <inertial>
          <mass>0.005</mass>
          <inertia>
            <ixx>1e-06</ixx>
            <ixy>0</ixy>
            <ixz>0</ixz>
            <iyy>1e-06</iyy>
            <iyz>0</iyz>
            <izz>1e-06</izz>
          </inertia>
          <pose>0 0 0 0 -0 0</pose>
        </inertial>
        <visual name='visual'>
          <geometry>
            <sphere>
              <radius>0.0113</radius>
            </sphere>
          </geometry>
          <material>
            <ambient>0 1 0 1</ambient>
            <diffuse>0 1 0 1</diffuse>
            <specular>0 1 0 1</specular>
          </material>
        </visual>
        <collision name='collision'>
          <geometry>
            <sphere>
              <radius>0.0113</radius>
            </sphere>
          </geometry>
          <max_contacts>10</max_contacts>
          <surface>
            <contact>
              <ode/>
            </contact>
            <bounce/>
            <friction>
              <torsional>
                <ode/>
              </torsional>
              <ode/>
            </friction>
          </surface>
        </collision>
        <self_collide>0</self_collide>
        <enable_wind>0</enable_wind>
        <kinematic>0</kinematic>
      </link>
      <joint name='cam_joint' type='fixed'>
        <pose relative_to='base_link'>0 0 0 0 -0 0</pose>
        <parent>base_link</parent>
        <child>cameraChassis</child>
        <axis>
          <xyz expressed_in='__model__'>1 0 0</xyz>
          <limit>
            <lower>-1.79769e+308</lower>
            <upper>1.79769e+308</upper>
          </limit>
        </axis>
      </joint>
      <joint name='leftWheel_joint' type='revolute'>
        <pose relative_to='leftWheel'>0 0 0 0 -0 0</pose>
        <parent>base_link</parent>
        <child>leftWheel</child>
        <axis>
          <xyz expressed_in='__model__'>0 1 0</xyz>
          <limit>
            <lower>-1.79769e+308</lower>
            <upper>1.79769e+308</upper>
          </limit>
          <dynamics>
            <spring_reference>0</spring_reference>
            <spring_stiffness>0</spring_stiffness>
          </dynamics>
        </axis>
      </joint>
      <joint name='rightWheel_joint' type='revolute'>
        <pose relative_to='rightWheel'>0 0 0 0 -0 0</pose>
        <parent>base_link</parent>
        <child>rightWheel</child>
        <axis>
          <xyz expressed_in='__model__'>0 1 0</xyz>
          <limit>
            <lower>-1.79769e+308</lower>
            <upper>1.79769e+308</upper>
          </limit>
          <dynamics>
            <spring_reference>0</spring_reference>
            <spring_stiffness>0</spring_stiffness>
          </dynamics>
        </axis>
      </joint>
      <joint name='caster_wheel' type='ball'>
        <parent>base_link</parent>
        <child>caster</child>
      </joint>
      <plugin name='differential_drive_controller' filename='libgazebo_ros_diff_drive.so'>
        <left_joint>leftWheel_joint</left_joint>
        <right_joint>rightWheel_joint</right_joint>
        <wheel_separation>0.08</wheel_separation>
        <wheel_diameter>0.057</wheel_diameter>
        <max_wheel_acceleration>1</max_wheel_acceleration>
        <max_wheel_torque>2</max_wheel_torque>
        <command_topic>cmd_vel</command_topic>
      </plugin>

      <sensor name='imu_sensor' type='imu'>
        <pose>0.0083 -0.04141 0.077 0 0 1.57079632679</pose>
        <always_on>1</always_on>
        <update_rate>50</update_rate>
        <imu>
          <topic>imu/data</topic>
        </imu>
        <plugin name='imu_plugin' filename='libgazebo_ros_imu.so'>
          <robotNamespace>/robot</robotNamespace>
          <topicName>imu</topicName>
          <bodyName>base_link</bodyName>
        </plugin>
      </sensor>  
    </model>


  </world>
</sdf>