<sdf version='1.7'>
  <world name='default'>

    <light name='sun' type='directional'>
      <cast_shadows>1</cast_shadows>
      <pose>0 0 10 0 -0 0</pose>
      <diffuse>0.8 0.8 0.8 1</diffuse>
      <specular>0.2 0.2 0.2 1</specular>

      <attenuation>
        <range>1000</range>
        <constant>0.9</constant>
        <linear>0.01</linear>
        <quadratic>0.001</quadratic>
      </attenuation>

      <direction>-0.5 0.1 -0.9</direction>

      <spot>
        <inner_angle>0</inner_angle>
        <outer_angle>0</outer_angle>
        <falloff>0</falloff>
      </spot>

    </light>

    <model name='ground_plane'>
      <static>1</static>
      <link name='link'>
        <collision name='collision'>
          <geometry>
            <plane>
              <normal>0 0 1</normal>
              <size>100 100</size>
            </plane>
          </geometry>
          <surface>
            <friction>
              <ode>
                <mu>100</mu>
                <mu2>50</mu2>
              </ode>
              <torsional>
                <ode/>
              </torsional>
            </friction>
            <contact>
              <ode/>
            </contact>
            <bounce/>
          </surface>
          <max_contacts>10</max_contacts>
        </collision>
        <visual name='visual'>
          <cast_shadows>0</cast_shadows>
          <geometry>
            <plane>
              <normal>0 0 1</normal>
              <size>100 100</size>
            </plane>
          </geometry>
          <material>
            <script>
              <uri>file://media/materials/scripts/gazebo.material</uri>
              <name>Gazebo/White</name>
            </script>
          </material>
        </visual>
        <self_collide>0</self_collide>
        <enable_wind>0</enable_wind>
        <kinematic>0</kinematic>
      </link>
    </model>

    <gravity>0 0 -9.8</gravity>
    <magnetic_field>6e-06 2.3e-05 -4.2e-05</magnetic_field>
    <atmosphere type='adiabatic'/>

    <physics type='ode'>
      <max_step_size>0.001</max_step_size>
      <real_time_factor>1</real_time_factor>
      <real_time_update_rate>1000</real_time_update_rate>
    </physics>

    <scene>
      <ambient>0.4 0.4 0.4 1</ambient>
      <background>0.7 0.7 0.7 1</background>
      <shadows>1</shadows>
    </scene>
    <audio>
      <device>default</device>
    </audio>
    <wind/>

    <spherical_coordinates>
      <surface_model>EARTH_WGS84</surface_model>
      <latitude_deg>0</latitude_deg>
      <longitude_deg>0</longitude_deg>
      <elevation>0</elevation>
      <heading_deg>0</heading_deg>
    </spherical_coordinates>

    <light name='user_directional_light_0' type='directional'>
      <pose>-0.337121 0.392333 1 0 -0 0</pose>
      <diffuse>0.5 0.5 0.5 1</diffuse>
      <specular>0.1 0.1 0.1 1</specular>
      <direction>0.1 0.1 -0.9</direction>
      <attenuation>
        <range>20</range>
        <constant>0.5</constant>
        <linear>0.01</linear>
        <quadratic>0.001</quadratic>
      </attenuation>
      <cast_shadows>1</cast_shadows>
      <spot>
        <inner_angle>0</inner_angle>
        <outer_angle>0</outer_angle>
        <falloff>0</falloff>
      </spot>
    </light>

    <state world_name='default'>
      <sim_time>207 742000000</sim_time>
      <real_time>76 531849887</real_time>
      <wall_time>1714377369 137823526</wall_time>
      <iterations>76414</iterations>

      <model name='ground_plane'>
        <pose>0 0 0 0 -0 0</pose>
        <scale>1 1 1</scale>
        <link name='link'>
          <pose>0 0 0 0 -0 0</pose>
          <velocity>0 0 0 0 -0 0</velocity>
          <acceleration>0 0 0 0 -0 0</acceleration>
          <wrench>0 0 0 0 -0 0</wrench>
        </link>
      </model>
      
      <light name='sun'>
        <pose>0 0 10 0 -0 0</pose>
      </light>
      <light name='user_directional_light_0'>
        <pose>-0.337121 0.392333 1 0 -0 0</pose>
      </light>
    </state>

    <model name='jetbot_sim' canonical_link='chassis'>
            <!-- <pose relative_to='world'>0 0 1 0 0 0</pose>   the pose is relative to the world by default -->

            <!-- <frame name="camera_frame" attached_to='chassis'>
                <pose>0.665 0 0.385 0 0.488692 0</pose>
            </frame> -->
            <link name='camera_chassis'>
                <pose relative_to="chassis">0.7 0 0.385 0 0.436332 0</pose> <!--angles are in radian-->
                <inertial>
                    <mass>0.1</mass>
                    <inertia>
                        <ixx>0.145833</ixx>
                        <ixy>0</ixy>
                        <ixz>0</ixz>
                        <iyy>0.145833</iyy>
                        <iyz>0</iyz>
                        <izz>0.125</izz>
                    </inertia>
                </inertial>
                <visual name='visual'>
                    <geometry>
                        <box>
                            <size>0.05 0.85 0.1</size> <!--question: this size is in meter-->
                        </box>
                    </geometry>
                    <material>
                        <ambient>0.0 0.0 1.0 1</ambient>
                        <diffuse>0.0 0.0 1.0 1</diffuse>
                        <specular>0.0 0.0 1.0 1</specular>
                    </material>
                </visual>
                <collision name='collision'>
                    <geometry>
                        <box>
                            <size>0.1 0.85 0.1</size>
                        </box>
                    </geometry>
                </collision>
            </link>

            <link name='chassis'>
                <pose relative_to='__model__'>0 0 0.4 0 0 0</pose>
                <inertial> <!--inertial properties of the link mass, inertia matix-->
                    <mass>11.4395</mass>
                    <inertia>
                        <ixx>0.688753</ixx>
                        <ixy>0</ixy>
                        <ixz>0</ixz>
                        <iyy>1.686278</iyy>
                        <iyz>0</iyz>
                        <izz>2.375031</izz>
                    </inertia>
                </inertial>
            <visual name='visual'>
                    <geometry>
                        <box>
                            <size>1.33 0.85 0.53</size> <!--question: this size is in meter-->
                        </box>
                    </geometry>
                    <material>
                        <ambient>0.0 0.0 1.0 1</ambient>
                        <diffuse>0.0 0.0 1.0 1</diffuse>
                        <specular>0.0 0.0 1.0 1</specular>
                    </material>
            </visual>
            <collision name='collision'>
                    <geometry>
                        <box>
                            <size>1.33 0.85 0.53</size>
                        </box>
                    </geometry>
            </collision>

            <sensor name="camera1" type="camera">
                <pose relative_to='camera_chassis'>0.05 0.0364902851051 0.05 0 0 0</pose>
                <topic>camera/left</topic>
                <camera>
                    <horizontal_fov>2.44346</horizontal_fov>
                    <image>
                    <width>500</width>
                    <height>300</height>
                    <format>L8</format>
                    </image>
                    <clip>
                        <near>0.1</near>
                        <far>100</far>
                    </clip>
                    <lens>
                    <!-- <scale_to_hfov>true</scale_to_hfov>  -->
                    <intrinsics>
                        <fx>307.99879313442784</fx>
                        <fy>328.57751082369407</fy>
                        <cx>280.24657373225784</cx>
                        <cy>134.9335316514946</cy>
                        <s>0</s>
                    </intrinsics>
                    </lens>
                </camera>
                <always_on>1</always_on>
                <update_rate>4</update_rate>
                <visualize>true</visualize>
                <plugin name="camera_controller1" filename="libgazebo_ros_camera.so">
                  <frame_name>camera_link_optical</frame_name>
                </plugin>
            </sensor>

            <sensor name="camera2" type="camera">
                <pose relative_to='camera_chassis'>0.05 -0.0364902851051 0.05 0 0 0</pose>
                <topic>camera/right</topic>
                <camera>
                    <horizontal_fov>2.44346</horizontal_fov>
                    <image>
                    <width>500</width>
                    <height>300</height>
                    <format>L8</format>
                    </image>
                    <clip>
                        <near>0.1</near>
                        <far>100</far>
                    </clip>
                    <lens>
                    <!-- <scale_to_hfov>true</scale_to_hfov>  -->
                    <intrinsics>
                        <fx>307.1754049460059</fx>
                        <fy>328.803046449949</fy>
                        <cx>265.74658118131305</cx>
                        <cy>141.73334383034592</cy>
                        <s>0</s>
                    </intrinsics>
                    </lens>
                </camera>
                <always_on>1</always_on>
                <update_rate>4</update_rate>
                <visualize>true</visualize>
                <plugin name="camera_controller2" filename="libgazebo_ros_camera.so">
                  <frame_name>camera_link_optical</frame_name>
                </plugin>
            </sensor>
            </link>
           
            <!--let's build the left wheel-->
            <link name='left_wheel'>
                <pose relative_to="chassis">0.35 0.44 -0.12 -1.5707 0 0</pose> <!--angles are in radian-->
                <inertial>
                    <mass>2</mass>
                    <inertia>
                        <ixx>0.145833</ixx>
                        <ixy>0</ixy>
                        <ixz>0</ixz>
                        <iyy>0.145833</iyy>
                        <iyz>0</iyz>
                        <izz>0.125</izz>
                    </inertia>
                </inertial>
                <visual name='visual'>
                    <geometry>
                        <cylinder>
                            <radius>0.285</radius>
                            <length>0.04</length>
                        </cylinder>
                    </geometry>
                    <material>
                        <ambient>1.0 0.0 0.0 1</ambient>
                        <diffuse>1.0 0.0 0.0 1</diffuse>
                        <specular>1.0 0.0 0.0 1</specular>
                    </material>
                </visual>
                <collision name='collision'>
                    <geometry>
                        <cylinder>
                            <radius>0.285</radius>
                            <length>0.04</length>
                        </cylinder>
                    </geometry>
                </collision>
            </link>

            <!--copy and paste for right wheel but change position-->
            <link name='right_wheel'>
                <pose relative_to="chassis">0.35 -0.44 -0.12 -1.5707 0 0</pose> <!--angles are in radian-->
                <inertial>
                    <mass>2</mass>
                    <inertia>
                        <ixx>0.040879</ixx>
                        <ixy>0</ixy>
                        <ixz>0</ixz>
                        <iyy>0.040879</iyy>
                        <iyz>0</iyz>
                        <izz>0.081225</izz>
                    </inertia>
                </inertial>
                <visual name='visual'>
                    <geometry>
                        <cylinder>
                            <radius>0.285</radius>
                            <length>0.04</length>
                        </cylinder>
                    </geometry>
                    <material>
                        <ambient>1.0 0.0 0.0 1</ambient>
                        <diffuse>1.0 0.0 0.0 1</diffuse>
                        <specular>1.0 0.0 0.0 1</specular>
                    </material>
                </visual>
                <collision name='collision'>
                    <geometry>
                        <cylinder>
                            <radius>0.285</radius>
                            <length>0.04</length>
                        </cylinder>
                    </geometry>
                </collision>
            </link>

            <frame name="caster_frame" attached_to='chassis'>
                <pose>-0.5 0 -0.271 0 0 0</pose>
            </frame>

            <!--caster wheel-->
            <link name='caster'>
                <pose relative_to='caster_frame'/>
                <inertial>
                    <mass>2</mass>
                    <inertia>
                        <ixx>0.01352</ixx>
                        <ixy>0</ixy>
                        <ixz>0</ixz>
                        <iyy>0.01352</iyy>
                        <iyz>0</iyz>
                        <izz>0.01352</izz>
                    </inertia>
                </inertial>
                <visual name='visual'>
                    <geometry>
                        <sphere>
                            <radius>0.13</radius>
                        </sphere>
                    </geometry>
                    <material>
                        <ambient>0.0 1 0.0 1</ambient>
                        <diffuse>0.0 1 0.0 1</diffuse>
                        <specular>0.0 1 0.0 1</specular>
                    </material>
                </visual>
                <collision name='collision'>
                    <geometry>
                        <sphere>
                            <radius>0.13</radius>
                        </sphere>
                    </geometry>
                </collision>
            </link>

            <!--connecting these links together using joints-->
            <joint name='cam_joint' type='fixed'> <!--continous joint is not supported yet-->
                <pose relative_to='chassis'/>
                <parent>chassis</parent>
                <child>camera_chassis</child>
                <axis>
                    <xyz expressed_in='__model__'>1 0 0</xyz> <!--can be descired to any frame or even arbitrary frames-->
                    <limit>
                        <lower>-1.79769e+308</lower>    <!--negative infinity-->
                        <upper>1.79769e+308</upper>     <!--positive infinity-->
                    </limit>
                </axis>
            </joint>

            <joint name='left_wheel_joint' type='revolute'> <!--continous joint is not supported yet-->
                <pose relative_to='left_wheel'/>
                <parent>chassis</parent>
                <child>left_wheel</child>
                <axis>
                    <xyz expressed_in='__model__'>0 1 0</xyz> <!--can be descired to any frame or even arbitrary frames-->
                    <limit>
                        <lower>-1.79769e+308</lower>    <!--negative infinity-->
                        <upper>1.79769e+308</upper>     <!--positive infinity-->
                    </limit>
                </axis>
            </joint>

            <joint name='right_wheel_joint' type='revolute'>
                <pose relative_to='right_wheel'/>
                <parent>chassis</parent>
                <child>right_wheel</child>
                <axis>
                    <xyz expressed_in='__model__'>0 1 0</xyz>
                    <limit>
                        <lower>-1.79769e+308</lower>    <!--negative infinity-->
                        <upper>1.79769e+308</upper>     <!--positive infinity-->
                    </limit>
                </axis>
            </joint>

            <!--different type of joints ball joint--> <!--defult value is the child-->
            <joint name='caster_wheel' type='ball'>
                <parent>chassis</parent>
                <child>caster</child>
            </joint>

            <plugin name='diff_drive' filename='libgazebo_ros_diff_drive.so'>

            <!-- <ros>
            <namespace>/jetbot</namespace>
            <remapping>cmd_vel:=cmd_jetbot</remapping>
            <remapping>odom:=odom_jetbot</remapping>
            </ros> -->

            <!-- wheels -->
            <left_joint>left_wheel_joint</left_joint>
            <right_joint>right_wheel_joint</right_joint>

            <!-- kinematics -->
            <wheel_separation>0.44</wheel_separation>
            <wheel_diameter>0.57</wheel_diameter>

            <!-- limits -->
            <max_wheel_torque>20</max_wheel_torque>
            <max_wheel_acceleration>1.0</max_wheel_acceleration>

            <!-- output -->
            <publish_odom>true</publish_odom>
            <publish_odom_tf>true</publish_odom_tf>
            <publish_wheel_tf>true</publish_wheel_tf>
<!-- 
            <odometry_frame>odom_jetbot</odometry_frame>
            <robot_base_frame>chassis</robot_base_frame> -->

        </plugin>
    </model>

    <gui fullscreen='0'>
      <camera name='user_camera'>
        <pose>5.81282 -23.4207 13.0604 -0 0.411456 1.70419</pose>
        <view_controller>orbit</view_controller>
        <projection_type>perspective</projection_type>
      </camera>
    </gui>



  </world>
</sdf>
