<sdf version='1.7'>
  <world name='default'>
<!-- PHYSIQUE -->
    <light name='sun' type='directional'>
      <cast_shadows>1</cast_shadows>
      <pose>0 0 10 0 -0 0</pose>
      <diffuse>0.8 0.8 0.8 1</diffuse>
      <specular>0.2 0.2 0.2 1</specular>
      <attenuation>
        <range>1000</range>
        <constant>0.9</constant>
        <linear>0.01</linear>
        <quadratic>0.001</quadratic>
      </attenuation>
      <direction>-0.5 0.1 -0.9</direction>
      <spot>
        <inner_angle>0</inner_angle>
        <outer_angle>0</outer_angle>
        <falloff>0</falloff>
      </spot>
    </light>
    <gravity>0 0 -9.8</gravity>
    <magnetic_field>6e-06 2.3e-05 -4.2e-05</magnetic_field>
    <atmosphere type='adiabatic'/>
    <physics type='ode'>
      <max_step_size>0.001</max_step_size>
      <real_time_factor>1</real_time_factor>
      <real_time_update_rate>1000</real_time_update_rate>
    </physics>
    <scene>
      <ambient>0.4 0.4 0.4 1</ambient>
      <background>0.7 0.7 0.7 1</background>
      <shadows>1</shadows>
    </scene>
    <audio>
      <device>default</device>
    </audio>
    <wind/>
    <spherical_coordinates>
      <surface_model>EARTH_WGS84</surface_model>
      <latitude_deg>0</latitude_deg>
      <longitude_deg>0</longitude_deg>
      <elevation>0</elevation>
      <heading_deg>0</heading_deg>
    </spherical_coordinates>
    <state world_name='default'>
      <sim_time>233 260000000</sim_time>
      <real_time>140 831837261</real_time>
      <wall_time>1716278405 110789169</wall_time>
      <iterations>140577</iterations>
<!--MODELS-->
      <model name='ground_plane'>
        <static>1</static>
        <link name='link'>
          <collision name='collision'>
            <geometry>
              <plane>
                <normal>0 0 1</normal>
                <size>100 100</size>
              </plane>
            </geometry>
            <surface>
              <friction>
                <ode>
                  <mu>100</mu>
                  <mu2>50</mu2>
                </ode>
                <torsional>
                  <ode/>
                </torsional>
              </friction>
              <contact>
                <ode/>
              </contact>
              <bounce/>
            </surface>
            <max_contacts>10</max_contacts>
          </collision>
          <visual name='visual'>
            <cast_shadows>0</cast_shadows>
            <geometry>
              <plane>
                <normal>0 0 1</normal>
                <size>100 100</size>
              </plane>
            </geometry>
            <material>
              <script>
                <uri>file://media/materials/scripts/gazebo.material</uri>
                <name>Gazebo/Grey</name>
              </script>
            </material>
          </visual>
          <self_collide>0</self_collide>
          <enable_wind>0</enable_wind>
          <kinematic>0</kinematic>
        </link>
      </model>
      <model name='jetson'>
        <pose>0.424273 2.90398 -0.460289 5.1e-05 -0.025445 0.500211</pose>
        <scale>1 1 1</scale>
        <link name='base_link'>
          <pose>0.413123 2.89786 0.039617 5.5e-05 -0.025151 0.500204</pose>
          <velocity>-0.000679 -3.8e-05 -0.000441 -0.000353 -0.033335 -0.005483</velocity>
          <acceleration>-0.078439 0.097849 -0.882078 2.43655 0.697543 -2.26478</acceleration>
          <wrench>-0.062751 0.078279 -0.705663 0 -0 0</wrench>
        </link>
        <link name='cameraChassis'>
          <pose>0.473667 2.93095 0.079818 5.1e-05 -0.025445 0.500211</pose>
          <velocity>-0.000559 -0.000498 5e-06 0.002266 -0.039227 -0.004574</velocity>
          <acceleration>-0.229959 -0.104444 0.010174 1.39051 -0.086429 -0.445591</acceleration>
          <wrench>-0.008738 -0.003969 0.000387 0 -0 0</wrench>
        </link>
        <link name='caster'>
          <pose>0.36986 2.87421 0.011295 -0.933885 0.562655 -2.83613</pose>
          <velocity>5.5e-05 0.000133 -0.008718 -0.018403 -0.142598 0</velocity>
          <acceleration>1.66975 -0.073293 -17.4369 0 -0 0</acceleration>
          <wrench>0.008349 -0.000366 -0.087185 0 -0 0</wrench>
        </link>
        <link name='leftWheel'>
          <pose>0.422987 2.95339 0.0285 1.57133 -0.920932 -2.64174</pose>
          <velocity>-8.3e-05 -0.000123 0.000232 0.004992 -0.002753 -0.002695</velocity>
          <acceleration>0.455927 0.043933 0.463953 2.17361 1.17963 -2.97854</acceleration>
          <wrench>0.007751 0.000747 0.007887 0 -0 0</wrench>
        </link>
        <link name='rightWheel'>
          <pose>0.465191 2.87618 0.0285 1.57077 -0.670826 -2.64132</pose>
          <velocity>-0.00074 -0.00012 0.001697 0.004283 -0.026688 -0.005784</velocity>
          <acceleration>0.055027 0.549694 3.39334 -3.09093 -0.635014 0.563869</acceleration>
          <wrench>0.000935 0.009345 0.057687 0 -0 0</wrench>
        </link>
      </model>
      <model name='textured_shapes'>
        <pose>5.84703 9.99174 0.5 0 -0 0.746349</pose>
        <scale>1 1 1</scale>
        <link name='box'>
          <pose>6.86547 8.89048 0.5 0 -0 0.746349</pose>
          <velocity>0 0 0 0 -0 0</velocity>
          <acceleration>-0 0 0 0 -0 0</acceleration>
          <wrench>-0 0 0 0 -0 0</wrench>
        </link>
        <link name='cylinder'>
          <pose>4.82859 11.093 0.499998 0 -0 0.746349</pose>
          <velocity>0 0 0 0 -0 0</velocity>
          <acceleration>0 0 -9.8 0 -0 0</acceleration>
          <wrench>0 0 -9.8 0 -0 0</wrench>
        </link>
        <link name='sphere'>
          <pose>5.84703 9.99174 0.5 0 -0 0.746349</pose>
          <velocity>0 0 0 0 -0 0</velocity>
          <acceleration>0 0 0 0 -0 0</acceleration>
          <wrench>0 0 0 0 -0 0</wrench>
        </link>
      </model>
      <light name='sun'>
        <pose>0 0 10 0 -0 0</pose>
      </light>
      <light name='user_directional_light_0'>
        <pose>33.4111 35.1657 1 0 -0 0</pose>
      </light>
      <light name='user_directional_light_1'>
        <pose>36.5096 -39.8155 1 0 -0 0</pose>
      </light>
      <light name='user_directional_light_2'>
        <pose>-36.7548 34.1905 1 0 -0 0</pose>
      </light>
      <light name='user_directional_light_3'>
        <pose>-41.0801 -40.7492 1 0 -0 0</pose>
      </light>
      <light name='user_directional_light_4'>
        <pose>-0.135201 -0.045924 1 0 -0 0</pose>
      </light>
    </state>
    <gui fullscreen='0'>
      <camera name='user_camera'>
        <pose>-11.6352 2.55207 4.83405 0 0.215643 0.704199</pose>
        <view_controller>orbit</view_controller>
        <projection_type>perspective</projection_type>
      </camera>
    </gui>


<!-- JETSON ROBOT -->
  <model name='jetson' canonical_link='base_link'>
  <!--LINK-->
    <!-- BASE LINK -->
      <link name='base_link'>
        <pose relative_to='__model__'>0 0 0.5 0 -0 0</pose>
        <inertial>
          <mass>0.8</mass>
          <inertia>
            <ixx>0.004</ixx>
            <ixy>0</ixy>
            <ixz>0</ixz>
            <iyy>0.004</iyy>
            <iyz>0</iyz>
            <izz>0.004</izz>
          </inertia>
          <pose>0 0 0 0 -0 0</pose>
        </inertial>
        <visual name='visual'>
          <geometry>
            <box>
              <size>0.133 0.085 0.053</size>
            </box>
          </geometry>
          <material>
            <ambient>0 0 1 1</ambient>
            <diffuse>0 0 1 1</diffuse>
            <specular>0 0 1 1</specular>
          </material>
        </visual>
        <collision name='collision'>
          <geometry>
            <box>
              <size>0.133 0.085 0.053</size>
            </box>
          </geometry>
          <max_contacts>10</max_contacts>
        </collision>
      </link>
    <!-- CAMERA LINK -->
      <link name='camera_link'>
        <pose relative_to='base_link'>0.07 0 0.0385 0 -0 0</pose>
        <inertial>
          <mass>0.038</mass>
          <inertia>
            <ixx>1e-06</ixx>
            <ixy>0</ixy>
            <ixz>0</ixz>
            <iyy>1e-06</iyy>
            <iyz>0</iyz>
            <izz>1e-06</izz>
          </inertia>
          <pose>0 0 0 0 -0 0</pose>
        </inertial>
        <visual name='visual'>
          <geometry>
            <box>
              <size>0.01 0.085 0.01</size>
            </box>
          </geometry>
          <material>
            <ambient>0 0 1 1</ambient>
            <diffuse>0 0 1 1</diffuse>
            <specular>0 0 1 1</specular>
          </material>
        </visual>
        <collision name='collision'>
          <geometry>
            <box>
              <size>0.01 0.085 0.01</size>
            </box>
          </geometry>
          <max_contacts>10</max_contacts>
          <surface>
            <contact>
              <ode/>
            </contact>
            <bounce/>
            <friction>
              <torsional>
                <ode/>
              </torsional>
              <ode/>
            </friction>
          </surface>
        </collision>
        
        <sensor name='cameraLeft' type='camera'>
          <pose relative_to='camera_chassis'>0 0.03649 0 0 -0 0</pose>
          <always_on>1</always_on>
          <update_rate>4</update_rate>
          <visualize>1</visualize>
          <topic>camera/left/</topic>
          <camera>
            <horizontal_fov>2.70526</horizontal_fov>
            <image>
              <width>500</width>
              <height>300</height>
              <format>L8</format>
            </image>
            <clip>
              <near>0.1</near>
              <far>100</far>
            </clip>
            <lens>
              <intrinsics>
                <fx>307.99879313442784</fx>
                <fy>328.57751082369407</fy>
                <cx>280.24657373225784</cx>
                <cy>134.9335316514946</cy>
                <s>0</s>
              </intrinsics>
              <projection>
                <p_fx>312.8884288345382</p_fx>
                <p_fy>312.8884288345382</p_fy>
                <p_cx>312.28302001953125</p_cx>
                <p_cy>135.72957611083984</p_cy>
                <tx>0.0</tx>
                <ty>0.0</ty>
              </projection>
            </lens>
          </camera>
          <plugin name='camera_left_controller' filename='libgazebo_ros_camera.so'>
            <camera_name>cameraLeft</camera_name>
            <frame_name>camera_left</frame_name>
            <hack_baseline>0.07298</hack_baseline>
            <min_depth>0.001</min_depth>
            <max_depth>5.0</max_depth>
         </plugin>
        </sensor>

        <sensor name='cameraRight' type='camera'>
          <pose relative_to='camera_chassis'>0.0665 -0.03649 0.0395 0 -0 0</pose>
            <always_on>1</always_on>
            <update_rate>4</update_rate>
            <visualize>1</visualize>
            <topic>camera/right/</topic>
            <camera>
              <horizontal_fov>2.70526</horizontal_fov>
              <image>
                <width>500</width>
                <height>300</height>
                <format>L8</format>
              </image>
              <clip>
                <near>0.1</near>
                <far>100</far>
              </clip>
              <lens>
                <intrinsics>
                  <fx>307.1754049460059</fx>
                  <fy>328.803046449949</fy>
                  <cx>265.74658118131305</cx>
                  <cy>141.73334383034592</cy>
                  <s>0</s>
                </intrinsics>
                <projection>
                  <p_fx>312.8884288345382</p_fx>
                  <p_fy>312.8884288345382</p_fy>
                  <p_cx>312.28302001953125</p_cx>
                  <p_cy>135.72957611083984</p_cy>
                  <tx>-22.834775948524072</tx>
                  <ty>0.0</ty>
                </projection>
              </lens>
            </camera>
            <plugin name='camera_right_controller' filename='libgazebo_ros_camera.so'>
              <camera_name>cameraRight</camera_name>
              <frame_name>camera_right</frame_name>
              <hack_baseline>0.07298</hack_baseline>
              <min_depth>0.001</min_depth>
              <max_depth>5.0</max_depth>
           </plugin> 
        </sensor>

      </link>

    <!-- IMU LINK -->
      <link name="imu_link">
          <gravity>true</gravity>
          <pose relative_to='base_link'>0.0083 -0.04141 0.0077 0 0 1.57079632679</pose>
          <inertial>
          <mass>0.00130</mass>
          <inertia>
            <ixx>1e-06</ixx>
            <ixy>0</ixy>
            <ixz>0</ixz>
            <iyy>1e-06</iyy>
            <iyz>0</iyz>
            <izz>1e-06</izz>
          </inertia>
          <pose>0 0 0 0 -0 0</pose>
          </inertial>
          <visual name='visual'>
            <geometry>
              <box>
                <size>0.018 0.0013 0.0012</size>
              </box>
            </geometry>
            <material>
              <ambient>0 1 0 1</ambient>
              <diffuse>0 1 0 1</diffuse>
              <specular>0 1 0 1</specular>
            </material>
          </visual>
          <collision name='collision'>
            <geometry>
              <box>
                <size>0.0018 0.0013 0.0012</size>
              </box>
            </geometry>
            <max_contacts>10</max_contacts>
            <surface>
              <contact>
                <ode/>
              </contact>
              <bounce/>
              <friction>
                <torsional>
                  <ode/>
                </torsional>
                <ode/>
              </friction>
            </surface>
          </collision>
          <sensor name="imu_jetson" type="imu">
            <always_on>true</always_on>
            <update_rate>50</update_rate>
            <imu>
              <angular_velocity>
                <x>
                  <noise type="gaussian">
                    <mean>0.0</mean>
                    <stddev>2e-4</stddev>
                  </noise>
                </x>
                <y>
                  <noise type="gaussian">
                    <mean>0.0</mean>
                    <stddev>2e-4</stddev>
                  </noise>
                </y>
                <z>
                  <noise type="gaussian">
                    <mean>0.0</mean>
                    <stddev>2e-4</stddev>
                  </noise>
                </z>
              </angular_velocity>
              <linear_acceleration>
                <x>
                  <noise type="gaussian">
                    <mean>0.0</mean>
                    <stddev>1.7e-2</stddev>
                  </noise>
                </x>
                <y>
                  <noise type="gaussian">
                    <mean>0.0</mean>
                    <stddev>1.7e-2</stddev>
                  </noise>
                </y>
                <z>
                  <noise type="gaussian">
                    <mean>0.0</mean>
                    <stddev>1.7e-2</stddev>
                  </noise>
                </z>
              </linear_acceleration>
              </imu>
              <plugin name="imu_jetson" filename="libgazebo_ros_imu.so">
              <initial_orientation_as_reference>false</initial_orientation_as_reference>
              <ros>
                <remapping>~/out:=/imu/data</remapping>
              </ros>
            </plugin>
            </sensor>
      </link>
    <!-- LEFT WHEEL LINK -->
      <link name='leftWheel'>
        <pose relative_to='base_link'>0.035 0.044 -0.012 -1.5707 0 0</pose>
        <inertial>
          <mass>0.017</mass>
          <inertia>
            <ixx>1e-06</ixx>
            <ixy>0</ixy>
            <ixz>0</ixz>
            <iyy>1e-06</iyy>
            <iyz>0</iyz>
            <izz>1e-06</izz>
          </inertia>
          <pose>0 0 0 0 -0 0</pose>
        </inertial>
        <visual name='visual'>
          <geometry>
            <cylinder>
              <radius>0.0285</radius>
              <length>0.004</length>
            </cylinder>
          </geometry>
          <material>
            <ambient>1 0 0 1</ambient>
            <diffuse>1 0 0 1</diffuse>
            <specular>1 0 0 1</specular>
          </material>
        </visual>
        <collision name='collision'>
          <geometry>
            <cylinder>
              <radius>0.0285</radius>
              <length>0.004</length>
            </cylinder>
            <surface>
              <friction>
                <ode>
                  <mu>0.8</mu>
                  <mu2>0.8</mu2>
                </ode>
              </friction>
            </surface>
          </geometry>
          <max_contacts>10</max_contacts>
          <surface>
            <contact>
              <ode/>
            </contact>
            <bounce/>
            <friction>
              <torsional>
                <ode/>
              </torsional>
              <ode/>
            </friction>
          </surface>
        </collision>
        <self_collide>0</self_collide>
        <enable_wind>0</enable_wind>
        <kinematic>0</kinematic>
      </link>
    <!-- RIGHT WHEEL LINK -->
      <link name='rightWheel'>
        <pose relative_to='base_link'>0.035 -0.044 -0.012 -1.5707 0 0</pose>
        <inertial>
          <mass>0.017</mass>
          <inertia>
            <ixx>2e-05</ixx>
            <ixy>0</ixy>
            <ixz>0</ixz>
            <iyy>2e-05</iyy>
            <iyz>0</iyz>
            <izz>4.1e-05</izz>
          </inertia>
          <pose>0 0 0 0 -0 0</pose>
        </inertial>
        <visual name='visual'>
          <geometry>
            <cylinder>
              <radius>0.0285</radius>
              <length>0.004</length>
            </cylinder>
            <surface>
              <friction>
                <ode>
                  <mu>0.8</mu>
                  <mu2>0.8</mu2>
                </ode>
              </friction>
            </surface>
          </geometry>
          <material>
            <ambient>1 0 0 1</ambient>
            <diffuse>1 0 0 1</diffuse>
            <specular>1 0 0 1</specular>
          </material>
        </visual>
        <collision name='collision'>
          <geometry>
            <cylinder>
              <radius>0.0285</radius>
              <length>0.004</length>
            </cylinder>
            <surface>
              <friction>
                <ode>
                  <mu>0.8</mu>
                  <mu2>0.8</mu2>
                </ode>
              </friction>
            </surface>
          </geometry>
          <max_contacts>10</max_contacts>
          <surface>
            <contact>
              <ode/>
            </contact>
            <bounce/>
            <friction>
              <torsional>
                <ode/>
              </torsional>
              <ode/>
            </friction>
          </surface>
        </collision>
        <self_collide>0</self_collide>
        <enable_wind>0</enable_wind>
        <kinematic>0</kinematic>
      </link>
    <!-- CASTER LINK -->
    <link name='caster'>
      <pose relative_to='base_link'>-0.05 0 -0.0271 0 -0 0</pose>
      <inertial>
        <mass>0.005</mass>
        <inertia>
          <ixx>1e-06</ixx>
          <ixy>0</ixy>
          <ixz>0</ixz>
          <iyy>1e-06</iyy>
          <iyz>0</iyz>
          <izz>1e-06</izz>
        </inertia>
        <pose>0 0 0 0 -0 0</pose>
      </inertial>
      <visual name='visual'>
        <geometry>
          <sphere>
            <radius>0.0113</radius>
          </sphere>
        </geometry>
        <material>
          <ambient>0 1 0 1</ambient>
          <diffuse>0 1 0 1</diffuse>
          <specular>0 1 0 1</specular>
        </material>
      </visual>
      <collision name='collision'>
        <geometry>
          <sphere>
            <radius>0.0113</radius>
          </sphere>
        </geometry>
        <max_contacts>10</max_contacts>
        <surface>
          <contact>
            <ode/>
          </contact>
          <bounce/>
          <friction>
            <torsional>
              <ode/>
            </torsional>
            <ode/>
          </friction>
        </surface>
      </collision>
      <self_collide>0</self_collide>
      <enable_wind>0</enable_wind>
      <kinematic>0</kinematic>
    </link>
  <!-- JOINTS -->

    <!-- CAMERA JOINT -->
    <joint name='cam_joint' type='fixed'>
      <pose relative_to='base_link'>0 0 0 0 -0 0</pose>
      <parent>base_link</parent>
      <child>camera_link</child>
      <axis>
        <xyz expressed_in='__model__'>1 0 0</xyz>
        <limit>
          <lower>-1.79769e+308</lower>
          <upper>1.79769e+308</upper>
        </limit>
      </axis>
    </joint>
    <!-- LEFT WHEEL JOINT -->
    <joint name='leftWheel_joint' type='revolute'>
      <pose relative_to='leftWheel'>0 0 0 0 -0 0</pose>
      <parent>base_link</parent>
      <child>leftWheel</child>
      <axis>
        <xyz expressed_in='__model__'>0 1 0</xyz>
        <limit>
          <lower>-1.79769e+308</lower>
          <upper>1.79769e+308</upper>
        </limit>
        <dynamics>
          <spring_reference>0</spring_reference>
          <spring_stiffness>0</spring_stiffness>
        </dynamics>
      </axis>
    </joint>
    <!-- RIGHT WHEEL JOINT -->
    <joint name='rightWheel_joint' type='revolute'>
      <pose relative_to='rightWheel'>0 0 0 0 -0 0</pose>
      <parent>base_link</parent>
      <child>rightWheel</child>
      <axis>
        <xyz expressed_in='__model__'>0 1 0</xyz>
        <limit>
          <lower>-1.79769e+308</lower>
          <upper>1.79769e+308</upper>
        </limit>
        <dynamics>
          <spring_reference>0</spring_reference>
          <spring_stiffness>0</spring_stiffness>
        </dynamics>
      </axis>
    </joint>
    <!-- CASTER JOINT -->
    <joint name='caster_wheel' type='ball'>
      <parent>base_link</parent>
      <child>caster</child>
    </joint>
    <!-- IMU JOINT -->
    <joint name="imu_joint" type="fixed">
      <parent>base_link</parent>
      <child>imu_link</child>
      <origin xyz="0.0083 -0.04141 0.0077"/>
    </joint>

  <!-- PLUGIN -->
    <plugin name='differential_drive_controller' filename='libgazebo_ros_diff_drive.so'>
      <left_joint>leftWheel_joint</left_joint>
      <right_joint>rightWheel_joint</right_joint>
      <wheel_separation>0.08</wheel_separation>
      <wheel_diameter>0.057</wheel_diameter>
      <max_wheel_acceleration>1</max_wheel_acceleration>
      <max_wheel_torque>2</max_wheel_torque>
      <command_topic>cmd_vel</command_topic>
    </plugin>
  </model>

<!-- LUMIERE -->
    <light name='user_directional_light_0' type='directional'>
      <pose>33.4111 35.1657 1 0 -0 0</pose>
      <diffuse>0.5 0.5 0.5 1</diffuse>
      <specular>0.1 0.1 0.1 1</specular>
      <direction>0.1 0.1 -0.9</direction>
      <attenuation>
        <range>20</range>
        <constant>0.5</constant>
        <linear>0.01</linear>
        <quadratic>0.001</quadratic>
      </attenuation>
      <cast_shadows>1</cast_shadows>
    </light>
    <light name='user_directional_light_1' type='directional'>
      <pose>36.5096 -39.8155 1 0 -0 0</pose>
      <diffuse>0.5 0.5 0.5 1</diffuse>
      <specular>0.1 0.1 0.1 1</specular>
      <direction>0.1 0.1 -0.9</direction>
      <attenuation>
        <range>20</range>
        <constant>0.5</constant>
        <linear>0.01</linear>
        <quadratic>0.001</quadratic>
      </attenuation>
      <cast_shadows>1</cast_shadows>
    </light>
    <light name='user_directional_light_2' type='directional'>
      <pose>-36.7548 34.1905 1 0 -0 0</pose>
      <diffuse>0.5 0.5 0.5 1</diffuse>
      <specular>0.1 0.1 0.1 1</specular>
      <direction>0.1 0.1 -0.9</direction>
      <attenuation>
        <range>20</range>
        <constant>0.5</constant>
        <linear>0.01</linear>
        <quadratic>0.001</quadratic>
      </attenuation>
      <cast_shadows>1</cast_shadows>
    </light>
    <light name='user_directional_light_3' type='directional'>
      <pose>-41.0801 -40.7492 1 0 -0 0</pose>
      <diffuse>0.5 0.5 0.5 1</diffuse>
      <specular>0.1 0.1 0.1 1</specular>
      <direction>0.1 0.1 -0.9</direction>
      <attenuation>
        <range>20</range>
        <constant>0.5</constant>
        <linear>0.01</linear>
        <quadratic>0.001</quadratic>
      </attenuation>
      <cast_shadows>1</cast_shadows>
    </light>
    <light name='user_directional_light_4' type='directional'>
      <pose>-0.135201 -0.045924 1 0 -0 0</pose>
      <diffuse>0.5 0.5 0.5 1</diffuse>
      <specular>0.1 0.1 0.1 1</specular>
      <direction>0.1 0.1 -0.9</direction>
      <attenuation>
        <range>20</range>
        <constant>0.5</constant>
        <linear>0.01</linear>
        <quadratic>0.001</quadratic>
      </attenuation>
      <cast_shadows>1</cast_shadows>
    </light>
    <model name='textured_shapes'>
      <pose>5.84703 9.99174 0.5 0 -0 0</pose>
      <link name='box'>
        <pose>0 -1.5 0 0 -0 0</pose>
        <collision name='collision'>
          <geometry>
            <box>
              <size>1 1 1</size>
            </box>
          </geometry>
          <max_contacts>10</max_contacts>
          <surface>
            <contact>
              <ode/>
            </contact>
            <bounce/>
            <friction>
              <torsional>
                <ode/>
              </torsional>
              <ode/>
            </friction>
          </surface>
        </collision>
        <visual name='visual'>
          <geometry>
            <box>
              <size>1 1 1</size>
            </box>
          </geometry>
          <material>
            <script>
              <uri>model://textured_shapes/materials/scripts</uri>
              <uri>model://textured_shapes/materials/textures</uri>
              <name>TexturedShape/Squares</name>
            </script>
          </material>
        </visual>
        <self_collide>0</self_collide>
        <inertial>
          <pose>0 0 0 0 -0 0</pose>
          <inertia>
            <ixx>1</ixx>
            <ixy>0</ixy>
            <ixz>0</ixz>
            <iyy>1</iyy>
            <iyz>0</iyz>
            <izz>1</izz>
          </inertia>
          <mass>1</mass>
        </inertial>
        <enable_wind>0</enable_wind>
        <kinematic>0</kinematic>
      </link>
      <link name='sphere'>
        <collision name='collision'>
          <geometry>
            <sphere>
              <radius>0.5</radius>
            </sphere>
          </geometry>
          <max_contacts>10</max_contacts>
          <surface>
            <contact>
              <ode/>
            </contact>
            <bounce/>
            <friction>
              <torsional>
                <ode/>
              </torsional>
              <ode/>
            </friction>
          </surface>
        </collision>
        <visual name='visual'>
          <geometry>
            <sphere>
              <radius>0.5</radius>
            </sphere>
          </geometry>
          <material>
            <script>
              <uri>model://textured_shapes/materials/scripts</uri>
              <uri>model://textured_shapes/materials/textures</uri>
              <name>TexturedShape/Squares</name>
            </script>
          </material>
        </visual>
        <self_collide>0</self_collide>
        <inertial>
          <pose>0 0 0 0 -0 0</pose>
          <inertia>
            <ixx>1</ixx>
            <ixy>0</ixy>
            <ixz>0</ixz>
            <iyy>1</iyy>
            <iyz>0</iyz>
            <izz>1</izz>
          </inertia>
          <mass>1</mass>
        </inertial>
        <enable_wind>0</enable_wind>
        <kinematic>0</kinematic>
      </link>
      <link name='cylinder'>
        <pose>0 1.5 0 0 -0 0</pose>
        <collision name='collision'>
          <geometry>
            <cylinder>
              <radius>0.5</radius>
              <length>1</length>
            </cylinder>
          </geometry>
          <max_contacts>10</max_contacts>
          <surface>
            <contact>
              <ode/>
            </contact>
            <bounce/>
            <friction>
              <torsional>
                <ode/>
              </torsional>
              <ode/>
            </friction>
          </surface>
        </collision>
        <visual name='visual'>
          <geometry>
            <cylinder>
              <radius>0.5</radius>
              <length>1</length>
            </cylinder>
          </geometry>
          <material>
            <script>
              <uri>model://textured_shapes/materials/scripts</uri>
              <uri>model://textured_shapes/materials/textures</uri>
              <name>TexturedShape/Squares</name>
            </script>
          </material>
        </visual>
        <self_collide>0</self_collide>
        <inertial>
          <pose>0 0 0 0 -0 0</pose>
          <inertia>
            <ixx>1</ixx>
            <ixy>0</ixy>
            <ixz>0</ixz>
            <iyy>1</iyy>
            <iyz>0</iyz>
            <izz>1</izz>
          </inertia>
          <mass>1</mass>
        </inertial>
        <enable_wind>0</enable_wind>
        <kinematic>0</kinematic>
      </link>
    </model>
  </world>
</sdf>
